<?xml version="1.0"?>
<robot xmlns:xacro="http://www.ros.org/wiki/xacro">
    <!--
        NOTES:
        Units:
            Distance: m
            Angles: rad (only option)
            Mass: kg
            Inertia: kg*m^2
            
        Notes on intertia:
            -The inertias are calculated for uniform density with weights that may or may not be accurate.
            At the time of this writing only the thumb flexor weight is correct. The palm is a 'best guess' 
            approximation and the fingers are likely off by an order of magnitude
        
        Notes on finger q2:
            -The hand is a 4 bar linkage mechanism forming an 'X'. 4 bar linkages are not supported in the 
            urdf format. The motion of the second finger joint is fully defined by the motion of the first 
            finger joint. The calculation to find the index finger second joint angle given the first is provided
            in a matlab script elsewhere in this repository.
    -->
    <xacro:macro name="pah" params="parent *origin hand_name">

        <material name="dark_grey">
            <color rgba="0.2 0.2 0.2 1.0" />
        </material>
        <material name="black">
            <color rgba="0.1 0.1 0.1 1.0" />
        </material>

    <joint name="base_link_to_base" type="fixed">
        <xacro:insert_block name="origin" />
        <parent link="${parent}" />
        <child link="${hand_name}_base" />
        <origin xyz="0 0 0" />
    </joint> 

    <!-- left hand starts here -->
    <link name="${hand_name}_base">
        <visual name="wrist_mesh">
            <origin rpy="0 0 0" xyz="0 0 0" />
            <geometry>
                <mesh filename="package://psyonic_description/urdf/meshes/wristmesh.STL" />
            </geometry>
            <material name="black"/>
        </visual>
        <inertial>
            <mass value="0.37511000" />
            <inertia ixx="3.76723021e-04" ixy="2.33895423e-06" ixz="-6.04325150e-06" iyy="4.67706269e-04" iyz="5.04572725e-05" izz="1.77650714e-04" />
            <origin xyz="-6.54520000e-04 -5.98838000e-03 5.07726500e-02" rpy="0 0 0" />
        </inertial>
        <visual name="palm_mesh">
            <origin rpy="3.14148426 0.08848813 3.14036612" xyz="24.0476665e-3 3.78124745e-3 32.32964923e-3" />
            <geometry>
                <mesh filename="package://psyonic_description/urdf/meshes/FB_palm_ref.STL" />
            </geometry>
            <material name="black"/> 
        </visual>
        <collision name="palm_mesh_coll">
            <origin rpy="3.14148426 0.08848813 3.14036612" xyz="24.0476665e-3 3.78124745e-3 32.32964923e-3" />
            <geometry>
                <mesh filename="package://psyonic_description/urdf/meshes/palm_hull.STL" />
            </geometry>
        </collision>
    </link>

    <link name="${hand_name}_index_L1">
        <inertial>
            <mass value="0.00636000" />
            <inertia ixx="2.85169621e-07" ixy="1.21454801e-08" ixz="2.02098452e-09" iyy="9.77683041e-07" iyz="-2.87547802e-10" izz="1.05411544e-06" />
            <origin xyz="1.77549969e-02 -2.13867669e-04 -2.02851433e-05" rpy="0 0 0" />
        </inertial>
        <visual name="index_mesh_1">
            <origin xyz="0 0 0" rpy="0 0 0" />
            <geometry>
                <mesh filename="package://psyonic_description/urdf/meshes/idx-F1.STL" />
            </geometry>
            <material name="dark_grey"/>
        </visual>
        <collision name="index_mesh_coll_1">
            <origin rpy="0 0 0.0844739" xyz="0.0384727 0.0032577 0" />
            <geometry>
                <mesh filename="package://psyonic_description/urdf/meshes/idx-F1-hull.STL" />
            </geometry>
        </collision>
    </link>
    <link name="${hand_name}_index_L2">
        <inertial>
            <mass value="0.00600000" />
            <inertia ixx="4.06340451e-07" ixy="3.99862338e-07" ixz="-1.91966414e-09" iyy="9.13745257e-07" iyz="8.96846813e-10" izz="1.13382499e-06" />
            <origin xyz="1.52723400e-02 -1.00039197e-02 -3.11063902e-05" rpy="0 0 0" />
        </inertial>
        <visual name="index_mesh_2">
            <origin rpy="0 0 0" xyz="0 0 0" />
            <geometry>
                <mesh filename="package://psyonic_description/urdf/meshes/idx-F2-Lg.STL" />
            </geometry>
            <material name="dark_grey"/> 
        </visual>
        <collision name="index_mesh_coll_2">
            <origin rpy="0 0 0" xyz="0.0091241 0 0" />
            <geometry>
                <mesh filename="package://psyonic_description/urdf/meshes/idx-F2-Lg-hull.STL" />
            </geometry>
        </collision>
    </link>
    <joint name="${hand_name}_index_q1" type="revolute">
        <parent link="${hand_name}_base" />
        <child link="${hand_name}_index_L1" />
        <origin xyz="0.028 -0.009 0.096" rpy="1.470 -1.317 -1.352" />
        <axis xyz="0 0 1" />
        <limit lower="0" upper="1.74" effort="6.0" velocity="8.0677777442" />
        
        <dynamics damping="0.001" friction="0.001" />
        
    </joint>
    <joint name="${hand_name}_index_q2" type="revolute">
        <parent link="${hand_name}_index_L1" />
        <child link="${hand_name}_index_L2" />
        <origin xyz="38.472723e-3 3.257695e-3 0.000000e-3" rpy="0 0 0.766" />
        <axis xyz="0 0 1" />
        <limit lower="0.00" upper="1.844" effort="6.0" velocity="8.0677777442" />
        
        <dynamics damping="0.001" friction="0.001" />
        
        <mimic joint="${hand_name}_index_q1" multiplier="1.05851325" />
    </joint>
    <link name="${hand_name}_index_anchor" />
    <joint name="${hand_name}_idx_anchor" type="fixed">
        <parent link="${hand_name}_index_L2" />
        <child link="${hand_name}_index_anchor" />
        <origin rpy="0 0 0" xyz="31.5541e-3  -10.44e-3 0.14e-3" />
    </joint>
    <link name="${hand_name}_fsr0" />
    <joint name="${hand_name}_fsr0" type="fixed">
        <parent link="${hand_name}_index_L2" />
        <child link="${hand_name}_fsr0" />
        <origin rpy="3.14 0 -0.1848" xyz="0.02936 -0.01697 -0.00435" />
    </joint>
    <link name="${hand_name}_fsr1" />
    <joint name="${hand_name}_fsr1" type="fixed">
        <parent link="${hand_name}_index_L2" />
        <child link="${hand_name}_fsr1" />
        <origin rpy="-1.5708 0.0 -0.2316" xyz="0.02961 -0.01394 0.0" />
    </joint>
    <link name="${hand_name}_fsr2" />
    <joint name="${hand_name}_fsr2" type="fixed">
        <parent link="${hand_name}_index_L2" />
        <child link="${hand_name}_fsr2" />
        <origin rpy="0.0 0.0 -0.1848036056311012" xyz="0.02936 -0.01697 0.00435" />
    </joint>
    <link name="${hand_name}_fsr3" />
    <joint name="${hand_name}_fsr3" type="fixed">
        <parent link="${hand_name}_index_L2" />
        <child link="${hand_name}_fsr3" />
        <origin rpy="3.14159 0.00000 -0.57092" xyz="0.01472 -0.01100 -0.00435" />
    </joint>
    <link name="${hand_name}_fsr4" />
    <joint name="${hand_name}_fsr4" type="fixed">
        <parent link="${hand_name}_index_L2" />
        <child link="${hand_name}_fsr4" />
        <origin rpy="0.00000 0.00000 -0.57199" xyz="0.01472 -0.01099 0.00435" />
    </joint>
    <link name="${hand_name}_fsr5" />
    <joint name="${hand_name}_fsr5" type="fixed">
        <parent link="${hand_name}_index_L2" />
        <child link="${hand_name}_fsr5" />
        <origin rpy="-2.66907 -1.57080 0.00000" xyz="0.03704 -0.01785 0.00000" />
    </joint>
    <link name="${hand_name}_middle_L1">
        <inertial>
            <mass value="0.00636000" />
            <inertia ixx="2.85169621e-07" ixy="1.21454801e-08" ixz="2.02098452e-09" iyy="9.77683041e-07" iyz="-2.87547802e-10" izz="1.05411544e-06" />
            <origin xyz="1.77549969e-02 -2.13867669e-04 -2.02851433e-05" rpy="0 0 0" />
        </inertial>
        <visual name="middle_mesh_1">
            <origin rpy="0 0 0" xyz="0 0 0" />
            <geometry>
                <mesh filename="package://psyonic_description/urdf/meshes/idx-F1.STL" />
            </geometry>
            <material name="dark_grey"/> 
        </visual>
        <collision name="middle_mesh_coll_1">
            <origin rpy="0 0 0.0844739" xyz="0.0384727 0.0032577 0" />
            <geometry>
                <mesh filename="package://psyonic_description/urdf/meshes/idx-F1-hull.STL" />
            </geometry>
        </collision>
    </link>
    <link name="${hand_name}_middle_L2">
        <inertial>
            <mass value="0.00600000" />
            <inertia ixx="4.06340451e-07" ixy="3.99862338e-07" ixz="-1.91966414e-09" iyy="9.13745257e-07" iyz="8.96846813e-10" izz="1.13382499e-06" />
            <origin xyz="1.52723400e-02 -1.00039197e-02 -3.11063902e-05" rpy="0 0 0" />
        </inertial>
        <visual name="middle_mesh_2">
            <origin rpy="0 0 0" xyz="0 0 0" />
            <geometry>
                <mesh filename="package://psyonic_description/urdf/meshes/idx-F2-Lg.STL" />
            </geometry>
            <material name="dark_grey"/> 
        </visual>
        <collision name="middle_mesh_coll_2">
            <origin rpy="0 0 0" xyz="0.0091241 0 0" />
            <geometry>
                <mesh filename="package://psyonic_description/urdf/meshes/idx-F2-Lg-hull.STL" />
            </geometry>
        </collision>
    </link>
    <joint name="${hand_name}_middle_q1" type="revolute">
        <parent link="${hand_name}_base" />
        <child link="${hand_name}_middle_L1" />
        <origin xyz="0.008 -0.012 0.099" rpy="1.629 -1.322 -1.583" />
        <limit lower="0" upper="1.74" effort="6.0" velocity="8.0677777442" />
        
        <dynamics damping="0.001" friction="0.001" />
        
        <axis xyz="0 0 1" />
    </joint>
    <joint name="${hand_name}_middle_q2" type="revolute">
        <parent link="${hand_name}_middle_L1" />
        <child link="${hand_name}_middle_L2" />
        <origin xyz="38.472723e-3 3.257695e-3 0.000000" rpy="0 0 0.766" />
        <axis xyz="0 0 1" />
        <limit lower="0.00" upper="1.844" effort="6.0" velocity="8.0677777442" />
        
        <dynamics damping="0.001" friction="0.001" />
        
        <mimic joint="${hand_name}_middle_q1" multiplier="1.05851325" />
    </joint>
    <link name="${hand_name}_middle_anchor" />
    <joint name="${hand_name}_mid_anchor" type="fixed">
        <parent link="${hand_name}_middle_L2" />
        <child link="${hand_name}_middle_anchor" />
        <origin rpy="0 0 0" xyz="31.5541e-3  -10.44e-3 0.14e-3" />
    </joint>
    <link name="${hand_name}_fsr6" />
    <joint name="${hand_name}_fsr6" type="fixed">
        <parent link="${hand_name}_middle_L2" />
        <child link="${hand_name}_fsr6" />
        <origin rpy="3.14 0 -0.1848" xyz="0.02936 -0.01697 -0.00435" />
    </joint>
    <link name="${hand_name}_fsr7" />
    <joint name="${hand_name}_fsr7" type="fixed">
        <parent link="${hand_name}_middle_L2" />
        <child link="${hand_name}_fsr7" />
        <origin rpy="-1.5708 0.0 -0.2316" xyz="0.02961 -0.01394 0.0" />
    </joint>
    <link name="${hand_name}_fsr8" />
    <joint name="${hand_name}_fsr8" type="fixed">
        <parent link="${hand_name}_middle_L2" />
        <child link="${hand_name}_fsr8" />
        <origin rpy="0.0 0.0 -0.1848036056311012" xyz="0.02936 -0.01697 0.00435" />
    </joint>
    <link name="${hand_name}_fsr9" />
    <joint name="${hand_name}_fsr9" type="fixed">
        <parent link="${hand_name}_middle_L2" />
        <child link="${hand_name}_fsr9" />
        <origin rpy="3.14159 0.00000 -0.57092" xyz="0.01472 -0.01100 -0.00435" />
    </joint>
    <link name="${hand_name}_fsr10" />
    <joint name="${hand_name}_fsr10" type="fixed">
        <parent link="${hand_name}_middle_L2" />
        <child link="${hand_name}_fsr10" />
        <origin rpy="0.00000 0.00000 -0.57199" xyz="0.01472 -0.01099 0.00435" />
    </joint>
    <link name="${hand_name}_fsr11" />
    <joint name="${hand_name}_fsr11" type="fixed">
        <parent link="${hand_name}_middle_L2" />
        <child link="${hand_name}_fsr11" />
        <origin rpy="-2.66907 -1.57080 0.00000" xyz="0.03704 -0.01785 0.00000" />
    </joint>
    <link name="${hand_name}_ring_L1">
        <inertial>
            <mass value="0.00636000" />
            <inertia ixx="2.85169621e-07" ixy="1.21454801e-08" ixz="2.02098452e-09" iyy="9.77683041e-07" iyz="-2.87547802e-10" izz="1.05411544e-06" />
            <origin xyz="1.77549969e-02 -2.13867669e-04 -2.02851433e-05" rpy="0 0 0" />
        </inertial>
        <visual name="ring_mesh_1">
            <origin rpy="0 0 0" xyz="0 0 0" />
            <geometry>
                <mesh filename="package://psyonic_description/urdf/meshes/idx-F1.STL" />
            </geometry>
            <material name="dark_grey"/> 
        </visual>
        <collision name="ring_mesh_coll_1">
            <origin rpy="0 0 0.0844739" xyz="0.0384727 0.0032577 0" />
            <geometry>
                <mesh filename="package://psyonic_description/urdf/meshes/idx-F1-hull.STL" />
            </geometry>
        </collision>
    </link>
    <link name="${hand_name}_ring_L2">
        <inertial>
            <mass value="0.00600000" />
            <inertia ixx="4.06340451e-07" ixy="3.99862338e-07" ixz="-1.91966414e-09" iyy="9.13745257e-07" iyz="8.96846813e-10" izz="1.13382499e-06" />
            <origin xyz="1.52723400e-02 -1.00039197e-02 -3.11063902e-05" rpy="0 0 0" />
        </inertial>
        <visual name="ring_mesh_2">
            <origin rpy="0 0 0" xyz="0 0 0" />
            <geometry>
                <mesh filename="package://psyonic_description/urdf/meshes/idx-F2-Lg.STL" />
            </geometry>
            <material name="dark_grey"/> 
        </visual>
        <collision name="ring_mesh_coll_2">
            <origin rpy="0 0 0" xyz="0.0091241 0 0" />
            <geometry>
                <mesh filename="package://psyonic_description/urdf/meshes/idx-F2-Lg-hull.STL" />
            </geometry>
        </collision>
    </link>
    <joint name="${hand_name}_ring_q1" type="revolute">
        <parent link="${hand_name}_base" />
        <child link="${hand_name}_ring_L1" />
        <origin xyz="-0.012 -0.010 0.097" rpy="1.780 -1.315 -1.811" />
        <limit lower="0" upper="1.74" effort="6.0" velocity="8.0677777442" />
        
        <dynamics damping="0.001" friction="0.001" />
        
        <axis xyz="0 0 1" />
    </joint>
    <joint name="${hand_name}_ring_q2" type="revolute">
        <parent link="${hand_name}_ring_L1" />
        <child link="${hand_name}_ring_L2" />
        <origin xyz="38.472723e-3 3.257695e-3 0.000000" rpy="0 0 0.766" />
        <axis xyz="0 0 1" />
        <limit lower="0.00" upper="1.844" effort="6.0" velocity="8.0677777442" />
        
        <dynamics damping="0.001" friction="0.001" />
        
        <mimic joint="${hand_name}_ring_q1" multiplier="1.05851325" />
    </joint>
    <link name="${hand_name}_ring_anchor" />
    <joint name="${hand_name}_rng_anchor" type="fixed">
        <parent link="${hand_name}_ring_L2" />
        <child link="${hand_name}_ring_anchor" />
        <origin rpy="0 0 0" xyz="31.5541e-3  -10.44e-3 0.14e-3" />
    </joint>
    <link name="${hand_name}_fsr12" />
    <joint name="${hand_name}_fsr12" type="fixed">
        <parent link="${hand_name}_ring_L2" />
        <child link="${hand_name}_fsr12" />
        <origin rpy="3.14 0 -0.1848" xyz="0.02936 -0.01697 -0.00435" />
    </joint>
    <link name="${hand_name}_fsr13" />
    <joint name="${hand_name}_fsr13" type="fixed">
        <parent link="${hand_name}_ring_L2" />
        <child link="${hand_name}_fsr13" />
        <origin rpy="-1.5708 0.0 -0.2316" xyz="0.02961 -0.01394 0.0" />
    </joint>
    <link name="${hand_name}_fsr14" />
    <joint name="${hand_name}_fsr14" type="fixed">
        <parent link="${hand_name}_ring_L2" />
        <child link="${hand_name}_fsr14" />
        <origin rpy="0.0 0.0 -0.1848036056311012" xyz="0.02936 -0.01697 0.00435" />
    </joint>
    <link name="${hand_name}_fsr15" />
    <joint name="${hand_name}_fsr15" type="fixed">
        <parent link="${hand_name}_ring_L2" />
        <child link="${hand_name}_fsr15" />
        <origin rpy="3.14159 0.00000 -0.57092" xyz="0.01472 -0.01100 -0.00435" />
    </joint>
    <link name="${hand_name}_fsr16" />
    <joint name="${hand_name}_fsr16" type="fixed">
        <parent link="${hand_name}_ring_L2" />
        <child link="${hand_name}_fsr16" />
        <origin rpy="0.00000 0.00000 -0.57199" xyz="0.01472 -0.01099 0.00435" />
    </joint>
    <link name="${hand_name}_fsr17" />
    <joint name="${hand_name}_fsr17" type="fixed">
        <parent link="${hand_name}_ring_L2" />
        <child link="${hand_name}_fsr17" />
        <origin rpy="-2.66907 -1.57080 0.00000" xyz="0.03704 -0.01785 0.00000" />
    </joint>
    <link name="${hand_name}_pinky_L1">
        <inertial>
            <mass value="0.00636000" />
            <inertia ixx="2.85169621e-07" ixy="1.21454801e-08" ixz="2.02098452e-09" iyy="9.77683041e-07" iyz="-2.87547802e-10" izz="1.05411544e-06" />
            <origin xyz="1.77549969e-02 -2.13867669e-04 -2.02851433e-05" rpy="0 0 0" />
        </inertial>
        <visual name="pinky_mesh_1">
            <origin rpy="0 0 0" xyz="0 0 0" />
            <geometry>
                <mesh filename="package://psyonic_description/urdf/meshes/idx-F1.STL" />
            </geometry>
            <material name="dark_grey"/> 
        </visual>
        <collision name="pinky_mesh_coll_1">
            <origin rpy="0 0 0.0844739" xyz="0.0384727 0.0032577 0" />
            <geometry>
                <mesh filename="package://psyonic_description/urdf/meshes/idx-F1-hull.STL" />
            </geometry>
        </collision>
    </link>
    <link name="${hand_name}_pinky_L2">
        <inertial>
            <mass value="0.00600000" />
            <inertia ixx="3.07970159e-07" ixy="2.80921010e-07" ixz="-2.72117073e-09" iyy="7.40775495e-07" iyz="1.08144438e-09" izz="8.93728844e-07" />
            <origin xyz="1.33249215e-02 -8.15894775e-03 -4.07689501e-05" rpy="0 0 0" />
        </inertial>
        <visual name="pinky_mesh_2">
            <origin rpy="0 0 0" xyz="0 0 0" />
            <geometry>
                <mesh filename="package://psyonic_description/urdf/meshes/idx-F2-Lg.STL" />
            </geometry>
            <material name="dark_grey"/> 
        </visual>
        <collision name="pinky_mesh_coll_2">
            <origin rpy="0 0 0" xyz="0.0091241 0 0" />
            <geometry>
                <mesh filename="package://psyonic_description/urdf/meshes/idx-F2-hull.STL" />
            </geometry>
        </collision>
    </link>
    <joint name="${hand_name}_pinky_q1" type="revolute">
        <parent link="${hand_name}_base" />
        <child link="${hand_name}_pinky_L1" />
        <origin xyz="-0.031 -0.007 0.091" rpy="1.731 -1.315 -1.828" />
        <limit lower="0" upper="1.74" effort="6.0" velocity="8.0677777442" />
        
        <dynamics damping="0.001" friction="0.001" />
        
        <axis xyz="0 0 1" />
    </joint>
    <joint name="${hand_name}_pinky_q2" type="revolute">
        <parent link="${hand_name}_pinky_L1" />
        <child link="${hand_name}_pinky_L2" />
        <origin xyz="38.472723e-3 3.257695e-3 0.000000" rpy="0 0 0.766" />
        <limit lower="0.00" upper="1.844" effort="6.0" velocity="8.0677777442" />
        
        <dynamics damping="0.001" friction="0.001" />
        
        <axis xyz="0 0 1" />
        <mimic joint="${hand_name}_pinky_q1" multiplier="1.05851325" />
    </joint>
    <link name="${hand_name}_pinky_anchor" />
    <joint name="${hand_name}_pnky_anchor" type="fixed">
        <parent link="${hand_name}_pinky_L2" />
        <child link="${hand_name}_pinky_anchor" />
        <origin rpy="0 0 0" xyz="31.5541e-3  -10.44e-3 0.14e-3" />
    </joint>
    <link name="${hand_name}_fsr18" />
    <joint name="${hand_name}_fsr18" type="fixed">
        <parent link="${hand_name}_pinky_L2" />
        <child link="${hand_name}_fsr18" />
        <origin rpy="3.14 0 -0.1848" xyz="0.02556 -0.01391 -0.00435" />
    </joint>
    <link name="${hand_name}_fsr19" />
    <joint name="${hand_name}_fsr19" type="fixed">
        <parent link="${hand_name}_pinky_L2" />
        <child link="${hand_name}_fsr19" />
        <origin rpy="-1.5708 0.0 -0.2316" xyz="0.02517 -0.01110 -0.00000" />
    </joint>
    <link name="${hand_name}_fsr20" />
    <joint name="${hand_name}_fsr20" type="fixed">
        <parent link="${hand_name}_pinky_L2" />
        <child link="${hand_name}_fsr20" />
        <origin rpy="0.0 0.0 -0.1848036056311012" xyz="0.02556 -0.01391 0.00435" />
    </joint>
    <link name="${hand_name}_fsr21" />
    <joint name="${hand_name}_fsr21" type="fixed">
        <parent link="${hand_name}_pinky_L2" />
        <child link="${hand_name}_fsr21" />
        <origin rpy="3.14159 0.00000 -0.57092" xyz="0.01310 -0.00943 -0.00435" />
    </joint>
    <link name="${hand_name}_fsr22" />
    <joint name="${hand_name}_fsr22" type="fixed">
        <parent link="${hand_name}_pinky_L2" />
        <child link="${hand_name}_fsr22" />
        <origin rpy="0.00000 0.00000 -0.57199" xyz="0.01310 -0.00943 0.00435" />
    </joint>
    <link name="${hand_name}_fsr23" />
    <joint name="${hand_name}_fsr23" type="fixed">
        <parent link="${hand_name}_pinky_L2" />
        <child link="${hand_name}_fsr23" />
        <origin rpy="-2.66907 -1.57080 0.00000" xyz="0.03142 -0.01438 0.00000" />
    </joint>
    <link name="${hand_name}_thumb_L1">
        <inertial>
            <mass value="0.00200000" />
            <inertia ixx="1.18180125e-07" ixy="2.01333778e-08" ixz="6.82164634e-08" iyy="2.49626759e-07" iyz="-8.51306376e-09" izz="2.02510886e-07" />
            <origin xyz="1.43350200e-02 -1.88501000e-03 -5.04062000e-03" rpy="0 0 0" />
        </inertial>
        <visual name="thumb_mesh_1">
            <origin rpy="0 0 0" xyz="0 0 0" />
            <geometry>
                <mesh filename="package://psyonic_description/urdf/meshes/thumb-F1.STL" />
            </geometry>
            <material name="dark_grey"/> 
        </visual>
        <collision name="thumb_coll_mesh_1">
            <origin rpy="-1.83260 0 0" xyz="0.02783 0 -0.01475" />
            <geometry>
                <mesh filename="package://psyonic_description/urdf/meshes/thumb-F1-hull.STL" />
            </geometry>
        </collision>
    </link>
    <link name="${hand_name}_thumb_L2">
        <inertial>
            <mass value="0.06000000" />
            <inertia ixx="8.10858595e-06" ixy="-7.50865361e-06" ixz="-6.23775212e-08" iyy="2.16060962e-05" iyz="-1.00035818e-07" izz="2.58546356e-05" />
            <origin xyz="2.77624500e-02 5.62171000e-03 -4.10855000e-03" rpy="0 0 0" />
        </inertial>
        <visual name="thumb_mesh_2">
            <origin rpy="0 0 0" xyz="0 0 0" />
            <geometry>
                <mesh filename="package://psyonic_description/urdf/meshes/thumb-F2-left.STL" />
            </geometry>
            <material name="dark_grey"/> 
        </visual>
        <collision name="thumb_hull_mesh_2">
            <origin rpy="3.14159 0 0.34383" xyz="0.06519 0.02334 -0.00393" />
            <geometry>
                <mesh filename="package://psyonic_description/urdf/meshes/thumb-F2-hull.STL" />
            </geometry>
        </collision>
    </link>
    <joint name="${hand_name}_thumb_q1" type="revolute">
        <parent link="${hand_name}_base" />
        <child link="${hand_name}_thumb_L1" />
        <origin xyz="24.0476665e-3 3.78124745e-3 32.32964923e-3" rpy="-3.1250458 -0.08693131 -0.1883423" />
        <axis xyz="0 0 1" />
        <limit lower="-1.74" upper="0" effort="1.2" velocity="40.338888721" />
        
        <dynamics damping="0.001" friction="0.001" />
        
    </joint>
    <joint name="${hand_name}_thumb_q2" type="revolute">
        <parent link="${hand_name}_thumb_L1" />
        <child link="${hand_name}_thumb_L2" />
        <origin xyz="27.8283501e-3 0 -14.7507000e-3" rpy="4.450589592585541 0 0" />
        <axis xyz="0 0 1" />
        <limit lower="0" upper="1.74" effort="6.0" velocity="8.0677777442" />
        
        <dynamics damping="0.001" friction="0.001" />
        
    </joint>
    <link name="${hand_name}_thumb_anchor" />
    <joint name="${hand_name}_thmb_anchor" type="fixed">
        <parent link="${hand_name}_thumb_L2" />
        <child link="${hand_name}_thumb_anchor" />
        <origin rpy="0 0 0" xyz="52.0012259e-3  28.0086971e-3 -.884835778e-3" />
    </joint>
    <link name="${hand_name}_fsr24" />
    <joint name="${hand_name}_fsr24" type="fixed">
        <parent link="${hand_name}_thumb_L2" />
        <child link="${hand_name}_fsr24" />
        <origin rpy="-2.29074 0.00001 0.41769" xyz="0.04747 0.01988 -0.00874" />
    </joint>
    <link name="${hand_name}_fsr25" />
    <joint name="${hand_name}_fsr25" type="fixed">
        <parent link="${hand_name}_thumb_L2" />
        <child link="${hand_name}_fsr25" />
        <origin rpy="-1.30899 0.00001 0.41769" xyz="0.04721 0.02124 -0.00106" />
    </joint>
    <link name="${hand_name}_fsr26" />
    <joint name="${hand_name}_fsr26" type="fixed">
        <parent link="${hand_name}_thumb_L2" />
        <child link="${hand_name}_fsr26" />
        <origin rpy="-0.32726 0.00001 0.41769" xyz="0.04896 0.01654 0.00491" />
    </joint>
    <link name="${hand_name}_fsr27" />
    <joint name="${hand_name}_fsr27" type="fixed">
        <parent link="${hand_name}_thumb_L2" />
        <child link="${hand_name}_fsr27" />
        <origin rpy="-2.29074 0.00001 0.41769" xyz="0.03739 0.01536 -0.00879" />
    </joint>
    <link name="${hand_name}_fsr28" />
    <joint name="${hand_name}_fsr28" type="fixed">
        <parent link="${hand_name}_thumb_L2" />
        <child link="${hand_name}_fsr28" />
        <origin rpy="-0.32726 0.00001 0.41769" xyz="0.03888 0.01200 0.00494" />
    </joint>
    <link name="${hand_name}_fsr29" />
    <joint name="${hand_name}_fsr29" type="fixed">
        <parent link="${hand_name}_thumb_L2" />
        <child link="${hand_name}_fsr29" />
        <origin rpy="-1.39339 0.19354 -0.40280" xyz="0.05591 0.02160 -0.00192" />
    </joint>

    </xacro:macro>
</robot>